{
  "data": {
    "lesson": {
      "_id": "63e90f67194b220e8fe5b53a",
      "title": " Exception Handling quiz",
      "courseId": "63a2eb428899436daf7eb489",
      "quizQuestions": [
        {
          "_id": "63e90f67194b224721e5b53b",
          "title": "<p>What is the purpose of the try and except keywords in Python?</p>",
          "options": [
            {
              "name": "<p>To handle errors and exceptions in a program.</p>"
            },
            {
              "name": "<p>To perform conditional operations.</p>"
            },
            {
              "name": "<p>To create user-defined functions.</p>"
            },
            {
              "name": "<p>To import modules.</p>"
            }
          ]
        },
        {
          "_id": "63e90f67194b220b03e5b53c",
          "title": "<p>What happens if an exception is raised in the try block?</p><p>&nbsp;</p>",
          "options": [
            {
              "name": "<p>The except block will be executed.</p>"
            },
            {
              "name": "<p>&nbsp;The program will continue to run.</p>"
            },
            {
              "name": "<p>The program will stop executing.</p>"
            },
            {
              "name": "<p>&nbsp;None of the above.</p>"
            }
          ]
        },
        {
          "_id": "63e90f67194b22f8f7e5b53d",
          "title": "<p>What happens if no exception is raised in the try block?</p><p>&nbsp;</p>",
          "options": [
            {
              "name": "<p>The except block will be executed.</p>"
            },
            {
              "name": "<p>&nbsp;The program will continue to run.</p>"
            },
            {
              "name": "<p>The program will stop executing.</p>"
            },
            {
              "name": "<p>&nbsp;None of the above.</p>"
            }
          ]
        },
        {
          "_id": "63e90f67194b225c77e5b53e",
          "title": "<p>What is the use of the finally keyword in exception handling?</p>",
          "options": [
            {
              "name": "<p>To handle exceptions and errors.</p>"
            },
            {
              "name": "<p>To specify a block of code that will be executed regardless of whether an exception was raised or not.</p>"
            },
            {
              "name": "<p>To create user-defined functions.</p>"
            },
            {
              "name": "<p>None of the above.</p>"
            }
          ]
        },
        {
          "_id": "63e90f67194b225ba6e5b53f",
          "title": "<p>What is a custom exception in Python?</p>",
          "options": [
            {
              "name": "<p><strong>&nbsp;</strong>A built-in exception</p>"
            },
            {
              "name": "<p>A user-defined exception</p>"
            },
            {
              "name": "<p><strong>&nbsp;</strong>Both A and B</p>"
            },
            {
              "name": "<p>none of the above</p>"
            }
          ]
        },
        {
          "_id": "63e90f67194b22b91de5b540",
          "title": "<p>can you create a custom exception in Python?</p>",
          "options": [
            {
              "name": "<p>By using the raise statement</p>"
            },
            {
              "name": "<p>By using the assert statement</p>"
            },
            {
              "name": "<p>Both A and B</p>"
            },
            {
              "name": "<p>none of the above</p>"
            }
          ]
        }
      ],
      "type": "quiz",
      "resources": [],
      "createdAt": "2023-02-12T16:10:15.353Z",
      "updatedAt": "2023-02-12T16:10:15.353Z",
      "__v": 0
    }
  }
}